<mujoco>
    <actuator>
        <motor gear="100000000" joint="hinge_1" name="pitch_motor" ctrlrange="-300 300" ctrllimited="true"/>
        <motor gear="100000000" joint="hinge_2" name="roll_motor" ctrlrange="-300 300" ctrllimited="true"/>
        <motor gear="100000000" joint="hinge_3" name="yaw_motor" ctrlrange="-300 300" ctrllimited="true"/>
        <motor gear="100000000" joint="elbow" name="elbow_motor" ctrlrange="-300 300" ctrllimited="true"/>
    </actuator>
    <asset>
        <material name="blue" rgba="0 0 1 1" />
        <material name="green" rgba="0 1 0 1" />
        <material name="red" rgba="1 0 0 1" />
        <material name="black" rgba=".1 .1 .3 .8" />
    </asset>
    <worldbody>
        <geom type="plane" size="1000 1000 0.1" pos="0 0 -1000" rgba="1 1 1 1" />
        <light diffuse=".5 .5 .5" pos="0 0 3" dir="0 0 -1" />
        <body name="torso" pos="0 0 0">
            <geom type="box" size="5 5 5" pos="0 0 0" euler="0 0 0" material="red"/>
            <geom type="box" size="2.5 2.5 2.5" pos="2.5 2.5 7.5" euler="0 0 0" material="red"/>
            <body name="pitch" pos="7.5 2.5 7.5">
                <geom type="cylinder" size="2.5 5" pos="0 0 0" euler="90 0 0" material="red" mass="10"/>
                <body name="roll" pos="0 7 0">
                    <joint name="hinge_1" pos="0 0 0" axis="0 1 0" />
                    <geom type="cylinder" size="2.5 2.5" pos="0 0 0" euler="0 0 90" material="red" mass="10"/>
                    <body name="yaw" pos="-5 0 0">
                        <joint name="hinge_2" pos="5 0 0" axis="0 0 1" />
                        <geom type="cylinder" size="2.5 2.5" pos="0 0 0" euler="0 90 0" material="red" mass="10"/>
                        <body name="link 1" pos="-5 0 0">
                            <joint name="hinge_3" pos="0 0 0" axis="1 0 0" />
                            <geom type="box" size="2.5 1 50" pos="-45 3.5 0" euler="0 90 0" material="green" mass="20"/>
                            <geom type="box" size="2.5 1 50" pos="-45 -3.5 0" euler="0 90 0" material="green" mass="20"/>
                            <geom type="cylinder" size="2.5 1" pos="-95 3.5 0" euler="90 0 0" material="green"/>
                            <geom type="cylinder" size="2.5 1" pos="-95 -3.5 0" euler="90 0 0" material="green"/>
                            <geom type="cylinder" size="2.5 4" pos="-95 0 0" euler="90 0 0" material="black" mass="10"/>
                            <body name="link2" pos="-100 0 0">
                                <joint name="elbow" pos="5 0 0" axis="0 1 0"/>
                                <geom type="box" size="2.5 2.5 50" pos="-45 0 0" euler="0 90 0" material="blue" mass="20"/>
                                <body name="endEffector" pos="-100 0 0">
                                    <geom type="sphere" size="5" pos="5 0 0" material="red" mass="10"/>
                                </body>

                            </body>
                        </body>

                    </body>
                </body>
            </body>
        </body>
    </worldbody>

</mujoco>
