<mujoco>
    <actuator>
        <motor gear="10" joint="hinge_1" name="pitch_motor" ctrlrange="-0.5 0.5" ctrllimited="true"/>
        <motor gear="10" joint="hinge_5" name="roll_motor" ctrlrange="-0.5 0.5" ctrllimited="true"/>
    </actuator>
    <asset>
        <material name="red" rgba="1 0 0 1"/>
        <material name="green" rgba="0 1 0 1"/>
        <material name="blue" rgba="0 0 1 1"/>
        <material name="white" rgba="1 1 1 1"/>
    </asset>
    <worldbody>
        <geom type="plane" size="1 1 .1" pos="0 0 -.5" material="white"/>
        <light diffuse=".5 .5 .5" pos="0 0 3" dir="0 0 -1" />
        <body name="motor1" pos="0 0 0">
            <geom type="box" size="0.02 0.02 0.05" pos="0 0 .05" euler="0 0 0" material="red"/>
            <geom type="cylinder" size=".0198 .0115" pos=".0396 0 .0802" euler="0 0 0" material="red"/>
            <body name="link1" pos=".043 0 .0802">
                <joint name="hinge_1" pos="0 0 0" axis="0 0 1" range="-180 180"/>
                <geom type="box" size="0.02 0.05 0.02" pos="0 -0.05 0.04" euler="0 0 0" material="blue"/>
                <geom type="box" size="0.02  0.02 0.1" pos="0 -0.1 0.14" euler="0 0 0" material="blue"/>
                <body name="endeffector" pos="0 -.15 .24">
                    <joint name="hinge_2" pos="0 0 0" axis="0 1 0" range="-180 180"/>
                    <geom type="box" size="0.02 0.1 0.02" pos="0 0.14 0.0" euler="0 0 0" material="green"/>
                    <geom type="box" size="0.02 0.02 0.1" pos="0 0.24 0.1" euler="0 0 0" material="green"/>
                    <body name="link2" pos="0 0.24 0.2">
                        <joint name="hinge_3" pos="0 0 0" axis="0 0 1" range="-180 180"/>
                        <geom type="box" size="0.05 0.02 0.02" pos="0.05 0 0.02" euler="0 0 0" material="blue"/>
                        <geom type="box" size="0.02 0.02 0.05" pos="0.1 0 -0.02" euler="0 0 0" material="blue"/>
                        <body name="link3" pos="0.1 0 -0.05">
                            <joint name="hinge_4" pos="0 0 0" axis="1 0 0" range="-180 180"/>
                            <geom type="box" size="0.02 0.05 0.02" pos="0 0.05 0" euler="0 0 0" material="blue"/>
                            <geom type="box" size="0.05 0.02 0.02" pos="-0.05 0.1 -0.02" euler="0 0 0" material="blue"/>
                            <body name="motor2" pos="-0.0902 0.129 -0.02">
                                <joint name="hinge_5" pos="0 0 0" axis="0 1 0" range="-180 180"/>
                                <geom type="cylinder" size=".0198 .0115" pos="0 0 0" euler="90 0 0" material="red"/>
                            </body>
                        </body>
                    </body>
                </body>
            </body>
        </body>
    </worldbody>
    <equality>
        <connect name="kinematic_link" active="true" body1="motor2"  anchor="0 0 0" />
    </equality>
</mujoco>
