<mujoco>
    <actuator>
        <motor gear="100000000" joint="hinge_1" name="pitch_motor" ctrlrange="-300 300" ctrllimited="true"/>
        <motor gear="100000000" joint="hinge_2" name="roll_motor" ctrlrange="-300 300" ctrllimited="true"/>
    </actuator>
    <asset>
        <material name="blue" rgba="0 0 1 1"/>
        <material name="white" rgba="1 1 1 1"/>
        <material name="yellow" rgba="1 1 0 1"/>
        <material name="red" rgba="1 0 0 1"/>
    </asset>
    <worldbody>

        <light diffuse=".5 .5 .5" pos="0 0 3" dir="0 0 -1" />
         <body name="j1" pos="0 0 0">
            <geom type="cylinder" size=".25 .25" pos="0 0 0" euler="90 0 0" material="yellow"/>
            <body name="link1" pos="0 0 0">
                <joint name="hinge_1" pos="0 0 0" axis="0 1 0" />
                <geom type="box" size=".25 .25 50" pos="-25 0 43.3" euler="0 -30 0" material="blue"/>
                <body name="j2" pos="-50 0 86.6">
                    <geom type="cylinder" size=".25 .25" pos="0 0 0" euler="90 0 0" material="white"/>
                    <body name="link2" pos="0 0 0">
                        <joint name="free1" pos="0 0 0" axis="0 1 0"/>
                        <geom type="box" size=".25 .25 50" pos="-25 0 43.3" euler="0 -30 0" material="blue"/>
                        <body name="end_effector" pos="-50 0 86.6">
                            <geom type="cylinder" size=".25 .25" pos="0 0 0" euler="90 0 0" material="white"/>
                            <body name="link3" pos="0 0 0">
                                <joint name="fn" pos="0 0 0" axis="0 1 0"/>
                                <geom type="box" size=".25 .25 50" pos="-25 0 -43.3" euler="0 30 0" material="blue"/>
                                <body name="j3" pos="-50 0 -86.6">
                                    <geom type="cylinder" size=".25 .25" pos="0 0 0" euler="90 0 0" material="white"/>
                                    <body name="link4" pos="0 0 0">
                                        <joint name="free2" pos="0 0 0" axis="0 1 0"/>
                                        <geom type="box" size=".25 .25 50" pos="-25 0 -43.3" euler="0 30 0" material="blue"/>
                                        <body name="j4" pos="-50 0 -86.6">
                                            <joint name="hinge_2" pos="0 0 0" axis="0 1 0"/>
                                            <geom type="cylinder" size=".25 .25" pos="0 0 0" euler="90 0 0" material="yellow"/>
                                        </body>
                                    </body>
                                </body>
                            </body>
                        </body>
                    </body>
                </body>
            </body>
        </body>
    </worldbody>
    <equality>
        <connect name="kinematic_link" active="true" body1="j4"  anchor="0 0 0" />
    </equality>
</mujoco>
