<mujoco>
    <actuator>
        <motor gear="10" joint="hinge_1" name="pitch_motor" ctrlrange="-0.5 0.5" ctrllimited="true"/>
        <motor gear="10" joint="hinge_2" name="roll_motor" ctrlrange="-0.5 0.5" ctrllimited="true"/>
        <motor gear="10" joint="hinge_3" name="yaw_motor" ctrlrange="-0.5 0.5" ctrllimited="true"/>
        <motor gear="10" joint="elbow" name="elbow_motor" ctrlrange="-0.5 0.5" ctrllimited="true"/>
    </actuator>
    <asset>
        <material name="blue" rgba="0 0 1 1" />
        <material name="green" rgba="0 1 0 1" />
        <material name="red" rgba="1 0 0 1" />
        <material name="black" rgba=".1 .1 .3 .8" />
    </asset>
    <worldbody>
        <geom type="plane" size="10 10 0.1" pos="0 0 -10" rgba="1 1 1 1" />
        <light diffuse=".5 .5 .5" pos="0 0 3" dir="0 0 -1" />
        <body name="torso" pos="0 0 0">
            <geom type="box" size=".05 .05 .05" pos="0 0 0" euler="0 0 0" material="red"/>
            <geom type="box" size=".025 .025 .025" pos=".025 .025 .075" euler="0 0 0" material="red"/>
            <body name="pitch" pos=".075 .025 .075">
                <geom type="cylinder" size=".0198 .0115" pos="0 0 0" euler="90 0 0" material="red" mass=".065"/>
                <body name="roll" pos="0 .0313 0">
                    <joint name="hinge_1" pos="0 0 0" axis="0 1 0" range="-3.14 3.14"/>
                    <geom type="cylinder" size=".0198 .0115" pos="0 0 0" euler="0 0 90" material="red" mass=".065"/>
                    <body name="yaw" pos=".0313 0 0">
                        <joint name="hinge_2" pos="-.0313 0 0" axis="0 0 1" range="-3.14 3.14"/>
                        <geom type="cylinder" size=".0198 .0115" pos="0 0 0" euler="0 90 0" material="red" mass=".065"/>
                        <body name="link 1" pos=".0198 0 0">
                            <joint name="hinge_3" pos="0 0 0" axis="1 0 0" range="-3.14 3.14"/>
                            <geom type="box" size=".0198 .001 0.05" pos=".045 .0191 0" euler="0 90 0" material="green" mass=".02"/>
                            <geom type="box" size=".0198 .001 0.05" pos=".045 -.0191 0" euler="0 90 0" material="green" mass=".02"/>
                            <geom type="cylinder" size=".0198 .001" pos=".09 .0191 0" euler="90 0 0" material="green"/>
                            <geom type="cylinder" size=".0198 .001" pos=".09 -.0191 0" euler="90 0 0" material="green"/>
                            <geom type="cylinder" size=".0198 .0115" pos=".09 0 0" euler="90 0 0" material="black" mass=".065"/>
                            <body name="link2" pos="0.09 0 0">
                                <joint name="elbow" pos="0 0 0" axis="0 1 0" range="-3.14 3.14"/>
                                <geom type="box" size=".0198 .001 0.05" pos=".0698 0 0" euler="0 90 0" material="blue" mass=".02"/>
                                <body name="endEffector" pos="0.09 0 0">
                                    <geom type="sphere" size=".0198" pos="0.05 0 0" material="red" mass=".050"/>
                                </body>
                            </body>
                        </body>
                    </body>
                </body>
            </body>
        </body>
    </worldbody>
</mujoco>
